Traceback (most recent call last):
  File "/home/larsm/anaconda3/envs/digital_tekstanalyse3.10/lib/python3.10/site-packages/jupyter_cache/executors/utils.py", line 51, in single_nb_execution
    executenb(
  File "/home/larsm/anaconda3/envs/digital_tekstanalyse3.10/lib/python3.10/site-packages/nbclient/client.py", line 1204, in execute
    return NotebookClient(nb=nb, resources=resources, km=km, **kwargs).execute()
  File "/home/larsm/anaconda3/envs/digital_tekstanalyse3.10/lib/python3.10/site-packages/nbclient/util.py", line 84, in wrapped
    return just_run(coro(*args, **kwargs))
  File "/home/larsm/anaconda3/envs/digital_tekstanalyse3.10/lib/python3.10/site-packages/nbclient/util.py", line 62, in just_run
    return loop.run_until_complete(coro)
  File "/home/larsm/anaconda3/envs/digital_tekstanalyse3.10/lib/python3.10/asyncio/base_events.py", line 649, in run_until_complete
    return future.result()
  File "/home/larsm/anaconda3/envs/digital_tekstanalyse3.10/lib/python3.10/site-packages/nbclient/client.py", line 663, in async_execute
    await self.async_execute_cell(
  File "/home/larsm/anaconda3/envs/digital_tekstanalyse3.10/lib/python3.10/site-packages/nbclient/client.py", line 965, in async_execute_cell
    await self._check_raise_for_error(cell, cell_index, exec_reply)
  File "/home/larsm/anaconda3/envs/digital_tekstanalyse3.10/lib/python3.10/site-packages/nbclient/client.py", line 862, in _check_raise_for_error
    raise CellExecutionError.from_cell_and_msg(cell, exec_reply_content)
nbclient.exceptions.CellExecutionError: An error occurred while executing the following cell:
------------------
#import dhlab.graph_networkx_louvain as gnl
# import dhlab.legacy.nbtext as nb
import dhlab.ngram.nb_ngram as nb
from dhlab.module_update import css
import networkx as nx
%matplotlib inline
plot = lambda x, lw=5: x.plot(figsize=(10,5), lw=lw)

# import dhlab.module_update as mu

# mu.update('graph_networkx_louvain')

import graph_networkx_louvain as gnl
------------------

[0;31m---------------------------------------------------------------------------[0m
[0;31mModuleNotFoundError[0m                       Traceback (most recent call last)
Cell [0;32mIn[1], line 13[0m
[1;32m      7[0m plot [38;5;241m=[39m [38;5;28;01mlambda[39;00m x, lw[38;5;241m=[39m[38;5;241m5[39m: x[38;5;241m.[39mplot(figsize[38;5;241m=[39m([38;5;241m10[39m,[38;5;241m5[39m), lw[38;5;241m=[39mlw)
[1;32m      9[0m [38;5;66;03m# import dhlab.module_update as mu[39;00m
[1;32m     10[0m 
[1;32m     11[0m [38;5;66;03m# mu.update('graph_networkx_louvain')[39;00m
[0;32m---> 13[0m [38;5;28;01mimport[39;00m [38;5;21;01mgraph_networkx_louvain[39;00m [38;5;28;01mas[39;00m [38;5;21;01mgnl[39;00m

[0;31mModuleNotFoundError[0m: No module named 'graph_networkx_louvain'
ModuleNotFoundError: No module named 'graph_networkx_louvain'

